[2019-02-28 19:10:14,462][Thread-1:4588][task_id:django.security.DisallowedHost][exception.py:80][ERROR][Invalid HTTP_HOST header: '192.168.19.200:8001'. You may need to add '192.168.19.200' to ALLOWED_HOSTS.]
[2019-02-28 19:10:15,715][Thread-3:1020][task_id:django.security.DisallowedHost][exception.py:80][ERROR][Invalid HTTP_HOST header: '192.168.19.200:8001'. You may need to add '192.168.19.200' to ALLOWED_HOSTS.]
[2019-02-28 19:10:38,854][Thread-5:7260][task_id:django.request][base.py:152][WARNING][Not Found: /favicon.ico]
[2019-02-28 19:10:48,497][Thread-6:6216][task_id:django.security.DisallowedHost][exception.py:80][ERROR][Invalid HTTP_HOST header: '192.168.19.200:8001'. You may need to add '192.168.19.200' to ALLOWED_HOSTS.]
[2019-02-28 19:10:48,928][Thread-7:1104][task_id:django.security.DisallowedHost][exception.py:80][ERROR][Invalid HTTP_HOST header: '192.168.19.200:8001'. You may need to add '192.168.19.200' to ALLOWED_HOSTS.]
[2019-02-28 19:11:03,090][Thread-8:1356][task_id:django.security.DisallowedHost][exception.py:80][ERROR][Invalid HTTP_HOST header: '192.168.19.200:8001'. You may need to add '192.168.19.200' to ALLOWED_HOSTS.]
[2019-02-28 19:11:03,400][Thread-9:5272][task_id:django.security.DisallowedHost][exception.py:80][ERROR][Invalid HTTP_HOST header: '192.168.19.200:8001'. You may need to add '192.168.19.200' to ALLOWED_HOSTS.]
[2019-02-28 19:11:22,321][Thread-4:1444][task_id:django.request][base.py:152][WARNING][Not Found: /sentory]
[2019-02-28 19:11:22,476][Thread-5:6072][task_id:django.request][base.py:152][WARNING][Not Found: /favicon.ico]
[2019-02-28 19:11:25,342][Thread-6:1552][task_id:django.request][base.py:152][WARNING][Not Found: /]
[2019-02-28 19:11:25,514][Thread-7:1084][task_id:django.request][base.py:152][WARNING][Not Found: /favicon.ico]
[2019-02-28 19:11:53,634][Thread-13:7892][task_id:django.request][base.py:152][WARNING][Not Found: /sentry/io]
[2019-02-28 19:12:04,319][Thread-14:5412][task_id:django.request][base.py:152][WARNING][Not Found: /sentry.io]
[2019-02-28 19:12:30,233][Thread-1:1956][task_id:django.request][exception.py:135][ERROR][Internal Server Error: /sentry/]
Traceback (most recent call last):
  File "C:\Python35\lib\site-packages\django\core\handlers\exception.py", line 41, in inner
    response = get_response(request)
  File "C:\Python35\lib\site-packages\django\core\handlers\base.py", line 187, in _get_response
    response = self.process_exception_by_middleware(e, request)
  File "C:\Python35\lib\site-packages\django\core\handlers\base.py", line 185, in _get_response
    response = wrapped_callback(request, *callback_args, **callback_kwargs)
  File "C:\Users\Administrator\Desktop\otherDemo\web\views.py", line 29, in sentry_demo
    raise ValueError("我错了")
ValueError: 我错了
[2019-02-28 19:12:56,029][Thread-4:7968][task_id:django.request][exception.py:135][ERROR][Internal Server Error: /sentry/]
Traceback (most recent call last):
  File "C:\Python35\lib\site-packages\django\core\handlers\exception.py", line 41, in inner
    response = get_response(request)
  File "C:\Python35\lib\site-packages\django\core\handlers\base.py", line 187, in _get_response
    response = self.process_exception_by_middleware(e, request)
  File "C:\Python35\lib\site-packages\django\core\handlers\base.py", line 185, in _get_response
    response = wrapped_callback(request, *callback_args, **callback_kwargs)
  File "C:\Users\Administrator\Desktop\otherDemo\web\views.py", line 29, in sentry_demo
    raise ValueError("我错了")
ValueError: 我错了
[2019-02-28 19:13:00,909][Thread-5:5412][task_id:django.request][exception.py:135][ERROR][Internal Server Error: /sentry/]
Traceback (most recent call last):
  File "C:\Python35\lib\site-packages\django\core\handlers\exception.py", line 41, in inner
    response = get_response(request)
  File "C:\Python35\lib\site-packages\django\core\handlers\base.py", line 187, in _get_response
    response = self.process_exception_by_middleware(e, request)
  File "C:\Python35\lib\site-packages\django\core\handlers\base.py", line 185, in _get_response
    response = wrapped_callback(request, *callback_args, **callback_kwargs)
  File "C:\Users\Administrator\Desktop\otherDemo\web\views.py", line 29, in sentry_demo
    raise ValueError("我错了")
ValueError: 我错了
[2019-02-28 19:13:11,195][Thread-6:6852][task_id:django.request][exception.py:135][ERROR][Internal Server Error: /sentry/]
Traceback (most recent call last):
  File "C:\Python35\lib\site-packages\django\core\handlers\exception.py", line 41, in inner
    response = get_response(request)
  File "C:\Python35\lib\site-packages\django\core\handlers\base.py", line 187, in _get_response
    response = self.process_exception_by_middleware(e, request)
  File "C:\Python35\lib\site-packages\django\core\handlers\base.py", line 185, in _get_response
    response = wrapped_callback(request, *callback_args, **callback_kwargs)
  File "C:\Users\Administrator\Desktop\otherDemo\web\views.py", line 29, in sentry_demo
    raise ValueError("我错了")
ValueError: 我错了
[2019-02-28 19:13:18,606][Thread-7:6624][task_id:django.request][exception.py:135][ERROR][Internal Server Error: /sentry/]
Traceback (most recent call last):
  File "C:\Python35\lib\site-packages\django\core\handlers\exception.py", line 41, in inner
    response = get_response(request)
  File "C:\Python35\lib\site-packages\django\core\handlers\base.py", line 187, in _get_response
    response = self.process_exception_by_middleware(e, request)
  File "C:\Python35\lib\site-packages\django\core\handlers\base.py", line 185, in _get_response
    response = wrapped_callback(request, *callback_args, **callback_kwargs)
  File "C:\Users\Administrator\Desktop\otherDemo\web\views.py", line 29, in sentry_demo
    raise ValueError("我错了")
ValueError: 我错了
[2019-02-28 19:13:30,062][Thread-8:3756][task_id:django.request][exception.py:135][ERROR][Internal Server Error: /sentry/]
Traceback (most recent call last):
  File "C:\Python35\lib\site-packages\django\core\handlers\exception.py", line 41, in inner
    response = get_response(request)
  File "C:\Python35\lib\site-packages\django\core\handlers\base.py", line 187, in _get_response
    response = self.process_exception_by_middleware(e, request)
  File "C:\Python35\lib\site-packages\django\core\handlers\base.py", line 185, in _get_response
    response = wrapped_callback(request, *callback_args, **callback_kwargs)
  File "C:\Users\Administrator\Desktop\otherDemo\web\views.py", line 29, in sentry_demo
    raise ValueError("我错了")
ValueError: 我错了
[2019-02-28 19:13:51,205][Thread-9:7504][task_id:django.request][exception.py:135][ERROR][Internal Server Error: /sentry/]
Traceback (most recent call last):
  File "C:\Python35\lib\site-packages\django\core\handlers\exception.py", line 41, in inner
    response = get_response(request)
  File "C:\Python35\lib\site-packages\django\core\handlers\base.py", line 187, in _get_response
    response = self.process_exception_by_middleware(e, request)
  File "C:\Python35\lib\site-packages\django\core\handlers\base.py", line 185, in _get_response
    response = wrapped_callback(request, *callback_args, **callback_kwargs)
  File "C:\Users\Administrator\Desktop\otherDemo\web\views.py", line 29, in sentry_demo
    raise ValueError("我错了")
ValueError: 我错了
[2019-02-28 19:14:01,978][Thread-11:3004][task_id:django.request][exception.py:135][ERROR][Internal Server Error: /sentry/]
Traceback (most recent call last):
  File "C:\Python35\lib\site-packages\django\core\handlers\exception.py", line 41, in inner
    response = get_response(request)
  File "C:\Python35\lib\site-packages\django\core\handlers\base.py", line 187, in _get_response
    response = self.process_exception_by_middleware(e, request)
  File "C:\Python35\lib\site-packages\django\core\handlers\base.py", line 185, in _get_response
    response = wrapped_callback(request, *callback_args, **callback_kwargs)
  File "C:\Users\Administrator\Desktop\otherDemo\web\views.py", line 29, in sentry_demo
    raise ValueError("我错了")
ValueError: 我错了
[2019-02-28 19:14:36,879][Thread-1:6612][task_id:django.request][exception.py:135][ERROR][Internal Server Error: /sentry/]
Traceback (most recent call last):
  File "C:\Python35\lib\site-packages\django\core\handlers\exception.py", line 41, in inner
    response = get_response(request)
  File "C:\Python35\lib\site-packages\django\core\handlers\base.py", line 187, in _get_response
    response = self.process_exception_by_middleware(e, request)
  File "C:\Python35\lib\site-packages\django\core\handlers\base.py", line 185, in _get_response
    response = wrapped_callback(request, *callback_args, **callback_kwargs)
  File "C:\Users\Administrator\Desktop\otherDemo\web\views.py", line 29, in sentry_demo
    raise ValueError("我错了")
ValueError: 我错了
[2019-02-28 19:17:11,029][Thread-1:1504][task_id:django.request][exception.py:135][ERROR][Internal Server Error: /sentry/]
Traceback (most recent call last):
  File "C:\Python35\lib\site-packages\django\core\handlers\exception.py", line 41, in inner
    response = get_response(request)
  File "C:\Python35\lib\site-packages\django\core\handlers\base.py", line 187, in _get_response
    response = self.process_exception_by_middleware(e, request)
  File "C:\Python35\lib\site-packages\django\core\handlers\base.py", line 185, in _get_response
    response = wrapped_callback(request, *callback_args, **callback_kwargs)
  File "C:\Users\Administrator\Desktop\otherDemo\web\views.py", line 29, in sentry_demo
    raise ValueError("我错了....")
ValueError: 我错了....
[2019-02-28 19:17:13,745][Thread-3:3992][task_id:django.request][exception.py:135][ERROR][Internal Server Error: /sentry/]
Traceback (most recent call last):
  File "C:\Python35\lib\site-packages\django\core\handlers\exception.py", line 41, in inner
    response = get_response(request)
  File "C:\Python35\lib\site-packages\django\core\handlers\base.py", line 187, in _get_response
    response = self.process_exception_by_middleware(e, request)
  File "C:\Python35\lib\site-packages\django\core\handlers\base.py", line 185, in _get_response
    response = wrapped_callback(request, *callback_args, **callback_kwargs)
  File "C:\Users\Administrator\Desktop\otherDemo\web\views.py", line 29, in sentry_demo
    raise ValueError("我错了....")
ValueError: 我错了....
[2019-02-28 19:17:24,664][Thread-5:7972][task_id:django.request][exception.py:135][ERROR][Internal Server Error: /sentry/]
Traceback (most recent call last):
  File "C:\Python35\lib\site-packages\django\core\handlers\exception.py", line 41, in inner
    response = get_response(request)
  File "C:\Python35\lib\site-packages\django\core\handlers\base.py", line 187, in _get_response
    response = self.process_exception_by_middleware(e, request)
  File "C:\Python35\lib\site-packages\django\core\handlers\base.py", line 185, in _get_response
    response = wrapped_callback(request, *callback_args, **callback_kwargs)
  File "C:\Users\Administrator\Desktop\otherDemo\web\views.py", line 29, in sentry_demo
    raise ValueError("我错了....")
ValueError: 我错了....
[2019-02-28 19:17:30,316][Thread-6:1528][task_id:django.request][exception.py:135][ERROR][Internal Server Error: /sentry/]
Traceback (most recent call last):
  File "C:\Python35\lib\site-packages\django\core\handlers\exception.py", line 41, in inner
    response = get_response(request)
  File "C:\Python35\lib\site-packages\django\core\handlers\base.py", line 187, in _get_response
    response = self.process_exception_by_middleware(e, request)
  File "C:\Python35\lib\site-packages\django\core\handlers\base.py", line 185, in _get_response
    response = wrapped_callback(request, *callback_args, **callback_kwargs)
  File "C:\Users\Administrator\Desktop\otherDemo\web\views.py", line 29, in sentry_demo
    raise ValueError("我错了....")
ValueError: 我错了....
[2019-02-28 19:17:30,484][Thread-7:3196][task_id:django.request][exception.py:135][ERROR][Internal Server Error: /sentry/]
Traceback (most recent call last):
  File "C:\Python35\lib\site-packages\django\core\handlers\exception.py", line 41, in inner
    response = get_response(request)
  File "C:\Python35\lib\site-packages\django\core\handlers\base.py", line 187, in _get_response
    response = self.process_exception_by_middleware(e, request)
  File "C:\Python35\lib\site-packages\django\core\handlers\base.py", line 185, in _get_response
    response = wrapped_callback(request, *callback_args, **callback_kwargs)
  File "C:\Users\Administrator\Desktop\otherDemo\web\views.py", line 29, in sentry_demo
    raise ValueError("我错了....")
ValueError: 我错了....
[2019-02-28 19:17:33,668][Thread-9:8076][task_id:django.request][exception.py:135][ERROR][Internal Server Error: /sentry/]
Traceback (most recent call last):
  File "C:\Python35\lib\site-packages\django\core\handlers\exception.py", line 41, in inner
    response = get_response(request)
  File "C:\Python35\lib\site-packages\django\core\handlers\base.py", line 187, in _get_response
    response = self.process_exception_by_middleware(e, request)
  File "C:\Python35\lib\site-packages\django\core\handlers\base.py", line 185, in _get_response
    response = wrapped_callback(request, *callback_args, **callback_kwargs)
  File "C:\Users\Administrator\Desktop\otherDemo\web\views.py", line 29, in sentry_demo
    raise ValueError("我错了....")
ValueError: 我错了....
[2019-02-28 19:17:47,171][Thread-10:8028][task_id:django.request][exception.py:135][ERROR][Internal Server Error: /sentry/]
Traceback (most recent call last):
  File "C:\Python35\lib\site-packages\django\core\handlers\exception.py", line 41, in inner
    response = get_response(request)
  File "C:\Python35\lib\site-packages\django\core\handlers\base.py", line 187, in _get_response
    response = self.process_exception_by_middleware(e, request)
  File "C:\Python35\lib\site-packages\django\core\handlers\base.py", line 185, in _get_response
    response = wrapped_callback(request, *callback_args, **callback_kwargs)
  File "C:\Users\Administrator\Desktop\otherDemo\web\views.py", line 29, in sentry_demo
    raise ValueError("我错了....")
ValueError: 我错了....
[2019-02-28 19:17:49,714][Thread-11:6340][task_id:django.request][exception.py:135][ERROR][Internal Server Error: /sentry/]
Traceback (most recent call last):
  File "C:\Python35\lib\site-packages\django\core\handlers\exception.py", line 41, in inner
    response = get_response(request)
  File "C:\Python35\lib\site-packages\django\core\handlers\base.py", line 187, in _get_response
    response = self.process_exception_by_middleware(e, request)
  File "C:\Python35\lib\site-packages\django\core\handlers\base.py", line 185, in _get_response
    response = wrapped_callback(request, *callback_args, **callback_kwargs)
  File "C:\Users\Administrator\Desktop\otherDemo\web\views.py", line 29, in sentry_demo
    raise ValueError("我错了....")
ValueError: 我错了....
[2019-02-28 19:17:54,192][Thread-12:1572][task_id:django.request][exception.py:135][ERROR][Internal Server Error: /sentry/]
Traceback (most recent call last):
  File "C:\Python35\lib\site-packages\django\core\handlers\exception.py", line 41, in inner
    response = get_response(request)
  File "C:\Python35\lib\site-packages\django\core\handlers\base.py", line 187, in _get_response
    response = self.process_exception_by_middleware(e, request)
  File "C:\Python35\lib\site-packages\django\core\handlers\base.py", line 185, in _get_response
    response = wrapped_callback(request, *callback_args, **callback_kwargs)
  File "C:\Users\Administrator\Desktop\otherDemo\web\views.py", line 29, in sentry_demo
    raise ValueError("我错了....")
ValueError: 我错了....
[2019-02-28 19:19:32,781][Thread-6:4296][task_id:django.request][base.py:152][WARNING][Not Found: /]
[2019-02-28 19:21:45,489][Thread-10:8104][task_id:django.request][exception.py:135][ERROR][Internal Server Error: /admin/login/]
Traceback (most recent call last):
  File "C:\Python35\lib\site-packages\django\db\backends\utils.py", line 64, in execute
    return self.cursor.execute(sql, params)
  File "C:\Python35\lib\site-packages\django\db\backends\sqlite3\base.py", line 328, in execute
    return Database.Cursor.execute(self, query, params)
sqlite3.OperationalError: no such table: auth_user

The above exception was the direct cause of the following exception:

Traceback (most recent call last):
  File "C:\Python35\lib\site-packages\django\core\handlers\exception.py", line 41, in inner
    response = get_response(request)
  File "C:\Python35\lib\site-packages\django\core\handlers\base.py", line 187, in _get_response
    response = self.process_exception_by_middleware(e, request)
  File "C:\Python35\lib\site-packages\django\core\handlers\base.py", line 185, in _get_response
    response = wrapped_callback(request, *callback_args, **callback_kwargs)
  File "C:\Python35\lib\site-packages\django\views\decorators\cache.py", line 57, in _wrapped_view_func
    response = view_func(request, *args, **kwargs)
  File "C:\Python35\lib\site-packages\django\contrib\admin\sites.py", line 393, in login
    return LoginView.as_view(**defaults)(request)
  File "C:\Python35\lib\site-packages\django\views\generic\base.py", line 68, in view
    return self.dispatch(request, *args, **kwargs)
  File "C:\Python35\lib\site-packages\django\utils\decorators.py", line 67, in _wrapper
    return bound_func(*args, **kwargs)
  File "C:\Python35\lib\site-packages\django\views\decorators\debug.py", line 76, in sensitive_post_parameters_wrapper
    return view(request, *args, **kwargs)
  File "C:\Python35\lib\site-packages\django\utils\decorators.py", line 63, in bound_func
    return func.__get__(self, type(self))(*args2, **kwargs2)
  File "C:\Python35\lib\site-packages\django\utils\decorators.py", line 67, in _wrapper
    return bound_func(*args, **kwargs)
  File "C:\Python35\lib\site-packages\django\utils\decorators.py", line 149, in _wrapped_view
    response = view_func(request, *args, **kwargs)
  File "C:\Python35\lib\site-packages\django\utils\decorators.py", line 63, in bound_func
    return func.__get__(self, type(self))(*args2, **kwargs2)
  File "C:\Python35\lib\site-packages\django\utils\decorators.py", line 67, in _wrapper
    return bound_func(*args, **kwargs)
  File "C:\Python35\lib\site-packages\django\views\decorators\cache.py", line 57, in _wrapped_view_func
    response = view_func(request, *args, **kwargs)
  File "C:\Python35\lib\site-packages\django\utils\decorators.py", line 63, in bound_func
    return func.__get__(self, type(self))(*args2, **kwargs2)
  File "C:\Python35\lib\site-packages\django\contrib\auth\views.py", line 90, in dispatch
    return super(LoginView, self).dispatch(request, *args, **kwargs)
  File "C:\Python35\lib\site-packages\django\views\generic\base.py", line 88, in dispatch
    return handler(request, *args, **kwargs)
  File "C:\Python35\lib\site-packages\django\views\generic\edit.py", line 182, in post
    if form.is_valid():
  File "C:\Python35\lib\site-packages\django\forms\forms.py", line 183, in is_valid
    return self.is_bound and not self.errors
  File "C:\Python35\lib\site-packages\django\forms\forms.py", line 175, in errors
    self.full_clean()
  File "C:\Python35\lib\site-packages\django\forms\forms.py", line 385, in full_clean
    self._clean_form()
  File "C:\Python35\lib\site-packages\django\forms\forms.py", line 412, in _clean_form
    cleaned_data = self.clean()
  File "C:\Python35\lib\site-packages\django\contrib\auth\forms.py", line 187, in clean
    self.user_cache = authenticate(self.request, username=username, password=password)
  File "C:\Python35\lib\site-packages\django\contrib\auth\__init__.py", line 70, in authenticate
    user = _authenticate_with_backend(backend, backend_path, request, credentials)
  File "C:\Python35\lib\site-packages\django\contrib\auth\__init__.py", line 116, in _authenticate_with_backend
    return backend.authenticate(*args, **credentials)
  File "C:\Python35\lib\site-packages\django\contrib\auth\backends.py", line 18, in authenticate
    user = UserModel._default_manager.get_by_natural_key(username)
  File "C:\Python35\lib\site-packages\django\contrib\auth\base_user.py", line 48, in get_by_natural_key
    return self.get(**{self.model.USERNAME_FIELD: username})
  File "C:\Python35\lib\site-packages\django\db\models\manager.py", line 85, in manager_method
    return getattr(self.get_queryset(), name)(*args, **kwargs)
  File "C:\Python35\lib\site-packages\django\db\models\query.py", line 374, in get
    num = len(clone)
  File "C:\Python35\lib\site-packages\django\db\models\query.py", line 232, in __len__
    self._fetch_all()
  File "C:\Python35\lib\site-packages\django\db\models\query.py", line 1121, in _fetch_all
    self._result_cache = list(self._iterable_class(self))
  File "C:\Python35\lib\site-packages\django\db\models\query.py", line 53, in __iter__
    results = compiler.execute_sql(chunked_fetch=self.chunked_fetch)
  File "C:\Python35\lib\site-packages\django\db\models\sql\compiler.py", line 899, in execute_sql
    raise original_exception
  File "C:\Python35\lib\site-packages\django\db\models\sql\compiler.py", line 889, in execute_sql
    cursor.execute(sql, params)
  File "C:\Python35\lib\site-packages\django\db\backends\utils.py", line 79, in execute
    return super(CursorDebugWrapper, self).execute(sql, params)
  File "C:\Python35\lib\site-packages\sentry_sdk\integrations\django\__init__.py", line 316, in execute
    return real_execute(self, sql, params)
  File "C:\Python35\lib\site-packages\django\db\backends\utils.py", line 64, in execute
    return self.cursor.execute(sql, params)
  File "C:\Python35\lib\site-packages\django\db\utils.py", line 94, in __exit__
    six.reraise(dj_exc_type, dj_exc_value, traceback)
  File "C:\Python35\lib\site-packages\django\utils\six.py", line 685, in reraise
    raise value.with_traceback(tb)
  File "C:\Python35\lib\site-packages\django\db\backends\utils.py", line 64, in execute
    return self.cursor.execute(sql, params)
  File "C:\Python35\lib\site-packages\django\db\backends\sqlite3\base.py", line 328, in execute
    return Database.Cursor.execute(self, query, params)
django.db.utils.OperationalError: no such table: auth_user
[2019-02-28 19:22:40,448][Thread-4:3756][task_id:django.request][exception.py:135][ERROR][Internal Server Error: /sentry/]
Traceback (most recent call last):
  File "C:\Python35\lib\site-packages\django\core\handlers\exception.py", line 41, in inner
    response = get_response(request)
  File "C:\Python35\lib\site-packages\django\core\handlers\base.py", line 187, in _get_response
    response = self.process_exception_by_middleware(e, request)
  File "C:\Python35\lib\site-packages\django\core\handlers\base.py", line 185, in _get_response
    response = wrapped_callback(request, *callback_args, **callback_kwargs)
  File "C:\Users\Administrator\Desktop\otherDemo\web\views.py", line 29, in sentry_demo
    raise ValueError("我错了....")
ValueError: 我错了....
[2019-02-28 19:22:40,448][Thread-1:1144][task_id:django.request][exception.py:135][ERROR][Internal Server Error: /sentry/]
Traceback (most recent call last):
  File "C:\Python35\lib\site-packages\django\core\handlers\exception.py", line 41, in inner
    response = get_response(request)
  File "C:\Python35\lib\site-packages\django\core\handlers\base.py", line 187, in _get_response
    response = self.process_exception_by_middleware(e, request)
  File "C:\Python35\lib\site-packages\django\core\handlers\base.py", line 185, in _get_response
    response = wrapped_callback(request, *callback_args, **callback_kwargs)
  File "C:\Users\Administrator\Desktop\otherDemo\web\views.py", line 29, in sentry_demo
    raise ValueError("我错了....")
ValueError: 我错了....
[2019-02-28 19:22:50,849][Thread-5:6652][task_id:utils.polyv][polyv.py:93][INFO][POLYV TOKEN RESULT： {'message': '', 'status': 'success', 'data': {'videoId': '03b56854c0970bde8598a0659e8cafa6_0', 'extraParams': 'HTML5', 'ttl': 600000, 'viewerName': 'customid', 'viewerIp': '127.0.0.1', 'createdTime': 1551352939410, 'iswxa': 0, 'expiredTime': 1551353539410, 'userId': '03b56854c0', 'disposable': False, 'token': '32b80976986b416a9cba563eaa91f36f', 'viewerId': 'customuserid'}, 'code': 200}]
[2019-02-28 19:22:59,815][Thread-8:6028][task_id:utils.polyv][polyv.py:93][INFO][POLYV TOKEN RESULT： {'message': '', 'status': 'success', 'data': {'videoId': '03b56854c0970bde8598a0659e8cafa6_0', 'extraParams': 'HTML5', 'ttl': 600000, 'viewerName': 'customid', 'viewerIp': '192.168.19.26', 'createdTime': 1551352948363, 'iswxa': 0, 'expiredTime': 1551353548363, 'userId': '03b56854c0', 'disposable': False, 'token': '210fe5940d8743ef9c15ec4369bcd15a', 'viewerId': 'customuserid'}, 'code': 200}]
[2019-02-28 19:23:22,303][Thread-9:7884][task_id:utils.polyv][polyv.py:93][INFO][POLYV TOKEN RESULT： {'message': '', 'status': 'success', 'data': {'videoId': '03b56854c0970bde8598a0659e8cafa6_0', 'extraParams': 'HTML5', 'ttl': 600000, 'viewerName': 'customid', 'viewerIp': '192.168.19.26', 'createdTime': 1551352970888, 'iswxa': 0, 'expiredTime': 1551353570888, 'userId': '03b56854c0', 'disposable': False, 'token': '210fe5940d8743ef9c15ec4369bcd15a', 'viewerId': 'customuserid'}, 'code': 200}]
[2019-02-28 19:23:27,337][Thread-10:5184][task_id:django.request][base.py:152][WARNING][Not Found: /video]
[2019-02-28 19:24:06,349][Thread-4:5240][task_id:django.request][base.py:152][WARNING][Not Found: /video]
[2019-02-28 19:24:06,389][Thread-1:7732][task_id:django.request][exception.py:135][ERROR][Internal Server Error: /sentry/]
Traceback (most recent call last):
  File "C:\Python35\lib\site-packages\django\core\handlers\exception.py", line 41, in inner
    response = get_response(request)
  File "C:\Python35\lib\site-packages\django\core\handlers\base.py", line 187, in _get_response
    response = self.process_exception_by_middleware(e, request)
  File "C:\Python35\lib\site-packages\django\core\handlers\base.py", line 185, in _get_response
    response = wrapped_callback(request, *callback_args, **callback_kwargs)
  File "C:\Users\Administrator\Desktop\otherDemo\web\views.py", line 29, in sentry_demo
    raise ValueError("我错了....")
ValueError: 我错了....
[2019-02-28 19:24:09,810][Thread-5:8164][task_id:django.request][base.py:152][WARNING][Not Found: /video]
[2019-02-28 19:24:14,252][Thread-6:1504][task_id:django.request][exception.py:135][ERROR][Internal Server Error: /sentry/]
Traceback (most recent call last):
  File "C:\Python35\lib\site-packages\django\core\handlers\exception.py", line 41, in inner
    response = get_response(request)
  File "C:\Python35\lib\site-packages\django\core\handlers\base.py", line 187, in _get_response
    response = self.process_exception_by_middleware(e, request)
  File "C:\Python35\lib\site-packages\django\core\handlers\base.py", line 185, in _get_response
    response = wrapped_callback(request, *callback_args, **callback_kwargs)
  File "C:\Users\Administrator\Desktop\otherDemo\web\views.py", line 29, in sentry_demo
    raise ValueError("我错了....")
ValueError: 我错了....
[2019-02-28 19:24:17,429][Thread-7:6956][task_id:django.request][exception.py:135][ERROR][Internal Server Error: /sentry/]
Traceback (most recent call last):
  File "C:\Python35\lib\site-packages\django\core\handlers\exception.py", line 41, in inner
    response = get_response(request)
  File "C:\Python35\lib\site-packages\django\core\handlers\base.py", line 187, in _get_response
    response = self.process_exception_by_middleware(e, request)
  File "C:\Python35\lib\site-packages\django\core\handlers\base.py", line 185, in _get_response
    response = wrapped_callback(request, *callback_args, **callback_kwargs)
  File "C:\Users\Administrator\Desktop\otherDemo\web\views.py", line 29, in sentry_demo
    raise ValueError("我错了....")
ValueError: 我错了....
[2019-02-28 19:25:08,667][Thread-8:6952][task_id:django.request][exception.py:135][ERROR][Internal Server Error: /sentry/]
Traceback (most recent call last):
  File "C:\Python35\lib\site-packages\django\core\handlers\exception.py", line 41, in inner
    response = get_response(request)
  File "C:\Python35\lib\site-packages\django\core\handlers\base.py", line 187, in _get_response
    response = self.process_exception_by_middleware(e, request)
  File "C:\Python35\lib\site-packages\django\core\handlers\base.py", line 185, in _get_response
    response = wrapped_callback(request, *callback_args, **callback_kwargs)
  File "C:\Users\Administrator\Desktop\otherDemo\web\views.py", line 29, in sentry_demo
    raise ValueError("我错了....")
ValueError: 我错了....
[2019-02-28 19:25:14,792][Thread-9:6044][task_id:django.request][base.py:152][WARNING][Not Found: /video]
[2019-02-28 19:25:19,596][Thread-10:8164][task_id:utils.polyv][polyv.py:93][INFO][POLYV TOKEN RESULT： {'message': '', 'code': 200, 'status': 'success', 'data': {'createdTime': 1551353088160, 'expiredTime': 1551353688160, 'extraParams': 'HTML5', 'viewerId': 'customuserid', 'viewerIp': '192.168.19.26', 'videoId': '03b56854c0970bde8598a0659e8cafa6_0', 'iswxa': 0, 'ttl': 600000, 'userId': '03b56854c0', 'token': '210fe5940d8743ef9c15ec4369bcd15a', 'disposable': False, 'viewerName': 'customid'}}]
[2019-02-28 19:25:40,415][Thread-11:7924][task_id:django.request][base.py:152][WARNING][Not Found: /ckeditor/]
[2019-02-28 19:25:52,607][Thread-3:3796][task_id:django.request][base.py:152][WARNING][Not Found: /ckeditor/]
[2019-02-28 19:26:00,311][Thread-5:3196][task_id:django.request][base.py:93][WARNING][Method Not Allowed (GET): /ckeditor/upload/]
[2019-02-28 19:26:02,070][Thread-7:156][task_id:django.request][exception.py:135][ERROR][Internal Server Error: /sentry/]
Traceback (most recent call last):
  File "C:\Python35\lib\site-packages\django\core\handlers\exception.py", line 41, in inner
    response = get_response(request)
  File "C:\Python35\lib\site-packages\django\core\handlers\base.py", line 187, in _get_response
    response = self.process_exception_by_middleware(e, request)
  File "C:\Python35\lib\site-packages\django\core\handlers\base.py", line 185, in _get_response
    response = wrapped_callback(request, *callback_args, **callback_kwargs)
  File "C:\Users\Administrator\Desktop\otherDemo\web\views.py", line 29, in sentry_demo
    raise ValueError("我错了....")
ValueError: 我错了....
[2019-02-28 19:26:04,322][Thread-4:5348][task_id:django.request][base.py:152][WARNING][Not Found: /ckeditor/]
[2019-02-28 19:26:18,795][Thread-17:5632][task_id:django.request][base.py:152][WARNING][Not Found: /]
[2019-02-28 19:26:28,443][Thread-20:7144][task_id:django.request][base.py:152][WARNING][Not Found: /ck]
[2019-02-28 19:26:29,893][Thread-19:8044][task_id:django.request][base.py:152][WARNING][Not Found: /ckeditor/]
[2019-02-28 19:26:36,806][Thread-23:6416][task_id:django.request][base.py:152][WARNING][Not Found: /ckeditor]
[2019-02-28 19:26:40,083][Thread-24:4128][task_id:django.request][base.py:152][WARNING][Not Found: /ckeditor/email]
[2019-02-28 19:26:45,481][Thread-28:7880][task_id:django.request][base.py:152][WARNING][Not Found: /media/]
[2019-02-28 19:26:48,329][Thread-29:6608][task_id:django.request][base.py:152][WARNING][Not Found: /media/]
[2019-02-28 19:26:54,366][Thread-30:6612][task_id:django.request][exception.py:135][ERROR][Internal Server Error: /sentry/]
Traceback (most recent call last):
  File "C:\Python35\lib\site-packages\django\core\handlers\exception.py", line 41, in inner
    response = get_response(request)
  File "C:\Python35\lib\site-packages\django\core\handlers\base.py", line 187, in _get_response
    response = self.process_exception_by_middleware(e, request)
  File "C:\Python35\lib\site-packages\django\core\handlers\base.py", line 185, in _get_response
    response = wrapped_callback(request, *callback_args, **callback_kwargs)
  File "C:\Users\Administrator\Desktop\otherDemo\web\views.py", line 29, in sentry_demo
    raise ValueError("我错了....")
ValueError: 我错了....
[2019-02-28 19:27:10,214][Thread-31:7084][task_id:django.request][base.py:152][WARNING][Not Found: /ckeditor/admin]
[2019-02-28 19:27:29,506][Thread-1:1524][task_id:django.request][exception.py:135][ERROR][Internal Server Error: /sentry/]
Traceback (most recent call last):
  File "C:\Python35\lib\site-packages\django\core\handlers\exception.py", line 41, in inner
    response = get_response(request)
  File "C:\Python35\lib\site-packages\django\core\handlers\base.py", line 187, in _get_response
    response = self.process_exception_by_middleware(e, request)
  File "C:\Python35\lib\site-packages\django\core\handlers\base.py", line 185, in _get_response
    response = wrapped_callback(request, *callback_args, **callback_kwargs)
  File "C:\Users\Administrator\Desktop\otherDemo\web\views.py", line 29, in sentry_demo
    raise ValueError("我错了....")
ValueError: 我错了....
[2019-02-28 19:27:50,505][raven-sentry.BackgroundWorker:2304][task_id:urllib3.connectionpool][connectionpool.py:673][WARNING][Retrying (Retry(total=2, connect=None, read=None, redirect=None, status=None)) after connection broken by 'NewConnectionError('<urllib3.connection.VerifiedHTTPSConnection object at 0x00000000054B1160>: Failed to establish a new connection: [WinError 10060] 由于连接方在一段时间后没有正确答复或连接的主机没有反应，连接尝试失败。',)': /api/1403698/store/]
[2019-02-28 19:36:50,344][Thread-1:3580][task_id:django.request][exception.py:135][ERROR][Internal Server Error: /ckeditor/write/]
Traceback (most recent call last):
  File "C:\Python35\lib\site-packages\django\core\handlers\exception.py", line 41, in inner
    response = get_response(request)
  File "C:\Python35\lib\site-packages\django\core\handlers\base.py", line 187, in _get_response
    response = self.process_exception_by_middleware(e, request)
  File "C:\Python35\lib\site-packages\django\core\handlers\base.py", line 185, in _get_response
    response = wrapped_callback(request, *callback_args, **callback_kwargs)
  File "C:\Users\Administrator\Desktop\otherDemo\web\views.py", line 118, in write
    form = CommentForm()
  File "C:\Python35\lib\site-packages\django\forms\models.py", line 295, in __init__
    raise ValueError('ModelForm has no model class specified.')
ValueError: ModelForm has no model class specified.
[2019-02-28 19:37:01,734][Thread-5:1148][task_id:django.request][exception.py:135][ERROR][Internal Server Error: /ckeditor/write/]
Traceback (most recent call last):
  File "C:\Python35\lib\site-packages\django\core\handlers\exception.py", line 41, in inner
    response = get_response(request)
  File "C:\Python35\lib\site-packages\django\core\handlers\base.py", line 187, in _get_response
    response = self.process_exception_by_middleware(e, request)
  File "C:\Python35\lib\site-packages\django\core\handlers\base.py", line 185, in _get_response
    response = wrapped_callback(request, *callback_args, **callback_kwargs)
  File "C:\Users\Administrator\Desktop\otherDemo\web\views.py", line 118, in write
    form = CommentForm()
  File "C:\Python35\lib\site-packages\django\forms\models.py", line 295, in __init__
    raise ValueError('ModelForm has no model class specified.')
ValueError: ModelForm has no model class specified.
[2019-02-28 19:37:09,443][Thread-6:6168][task_id:django.request][exception.py:135][ERROR][Internal Server Error: /ckeditor/write/]
Traceback (most recent call last):
  File "C:\Python35\lib\site-packages\django\core\handlers\exception.py", line 41, in inner
    response = get_response(request)
  File "C:\Python35\lib\site-packages\django\core\handlers\base.py", line 187, in _get_response
    response = self.process_exception_by_middleware(e, request)
  File "C:\Python35\lib\site-packages\django\core\handlers\base.py", line 185, in _get_response
    response = wrapped_callback(request, *callback_args, **callback_kwargs)
  File "C:\Users\Administrator\Desktop\otherDemo\web\views.py", line 118, in write
    form = CommentForm()
  File "C:\Python35\lib\site-packages\django\forms\models.py", line 295, in __init__
    raise ValueError('ModelForm has no model class specified.')
ValueError: ModelForm has no model class specified.
[2019-02-28 19:37:20,002][Thread-6:6588][task_id:django.request][base.py:152][WARNING][Not Found: /write]
[2019-02-28 19:52:19,128][Thread-8:5860][task_id:django.request][base.py:93][WARNING][Method Not Allowed (GET): /ckeditor/upload/]
